[32mINFO    [0m pytest_logger:log_util.py:49 Test data file found and loaded
[32mINFO    [0m pytest_logger:log_util.py:49 The HTTP request was successful.
[32mINFO    [0m pytest_logger:log_util.py:49 The HTTP request was successful.
[32mINFO    [0m pytest_logger:log_util.py:49 The DELETE request was successful.
[1m[31mERROR   [0m pytest_logger:log_util.py:53 An error occurred during the GET request.